<!--无约束门，只能关-->
<mujoco model="jk5">
    <compiler angle="radian" meshdir="../meshes/" coordinate="local"/>
    <size njmax="5000" nconmax="1000"/>
    <option timestep="2e-3" noslip_iterations="20">
        <flag contact="enable" warmstart="disable"/>
    </option>
    <visual>
        <map force="1" torque="10000"/>
        <rgba contactforce="1 0 0 1" contacttorque="0 1 0 1" contactfriction="0 0 1 1"/>
    </visual>
    <asset>
        <material name="common_mat" specular="0" shininess="0.5" reflectance="0" rgba="0.93 0.93 0.93 1"/>
        <material name='floor_mat' texture="floor_tex" shininess="0.8" texrepeat="10 10" specular="0.7"
                  reflectance="0.5"/>
        <material name="MatMetal" specular="1" shininess="0.3" rgba="0.9 0.9 0.9 1"/>
        <material name="MatDarkWood" texrepeat="3 3" specular="0.4" shininess="0.1"/>
        <material name="MatLightWood" texrepeat="3 3" specular="0.4" shininess="0.1"/>
        <texture type="skybox" builtin="gradient" rgb1="1 1 1" rgb2="1 1 1" width="512" height="512"/>
        <texture name="floor_tex" type="2d" builtin="checker" rgb1=".2 .3 .4" rgb2=".1 .2 .3" width="100" height="100"/>
        <hfield name="sin_floor" file="shape.png" nrow="0" ncol="0" size="0.25 0.2 0.02 0.01"/>
        <mesh name="base_link" file="base_link.STL"/>
        <mesh name="link1" file="link1.STL"/>
        <mesh name="link2" file="link2.STL"/>
        <mesh name="link3" file="link3.STL"/>
        <mesh name="link4" file="link4.STL"/>
        <mesh name="link5" file="link5.STL"/>
        <mesh name="link6" file="link6.STL"/>
    </asset>
    <worldbody>
        <light name="light" mode="targetbody" target="link1" directional="true" pos="1 1 3"/>
        <geom name='floor' material="floor_mat" pos='0 0 0' size='2.5 2.5 0.1' type='plane'/>
        <geom name="wall" material="MatLightWood" pos="-0.03 0.41 0.3" size=" 0.03 0.7 0.3" type="box"/>
        <!--0.3885用于平齐门把手,quat为 0 0 1,1 0 0, 0 1 0-->
        <body name="jk5" pos="0 0 0.3885" quat="0.5 0.5 0.5 0.5">
            <geom type="mesh" contype="0" conaffinity="0" group="1" rgba="1 1 1 1" mesh="base_link"/>
            <body name="link1" pos="0 0 0.069">
                <inertial pos="-3.8005e-05 -0.0024889 0.054452" quat="0.696512 0.0244353 -0.0262529 0.716648"
                          mass="4.27" diaginertia="0.0214324 0.0213196 0.00795099"/>
                <joint name="joint1" pos="0 0 0" axis="0 0 1" limited="true" range="-3.14 3.14"/>
                <geom type="mesh" contype="0" conaffinity="0" group="1" rgba="0 0.8 1 1" mesh="link1"/>
                <body name="link2" pos="0 0 0.073" quat="0.7071067811865475 0.7071067811865475 0 0">
                    <inertial pos="0 0.21252 0.12053" quat="0.414451 0.57284 0.573072 0.414334" mass="10.1"
                              diaginertia="1.01715 0.953511 0.0834946"/>
                    <joint name="joint2" pos="0 0 0" axis="0 0 1" limited="true" range="-3.14 3.14"/>
                    <geom type="mesh" contype="0" conaffinity="0" group="1" rgba="1 1 1 1" mesh="link2"/>
                    <body name="link3" pos="0 0.425 0" quat="0.7071067811865475 0 0 0.7071067811865475">
                        <inertial pos="0.27205 1.9634e-05 0.023591" quat="0.482588 0.516912 0.516005 0.483374"
                                  mass="2.61" diaginertia="0.262358 0.261811 0.0036704"/>
                        <joint name="joint3" pos="0 0 0" axis="0 0 1" limited="true" range="-3.14 3.14"/>
                        <geom type="mesh" contype="0" conaffinity="0" group="1" rgba="1 1 1 1" mesh="link3"/>
                        <body name="link4" pos="0.395 0 0">
                            <inertial pos="3.0707e-05 -0.015152 0.11185"
                                      quat="0.997531 0.0701668 0.000322345 -0.00295604" mass="1.45"
                                      diaginertia="0.0201018 0.0196889 0.00158379"/>
                            <joint name="joint4" pos="0 0 0" axis="0 0 1" limited="true" range="-3.14 3.14"/>
                            <geom type="mesh" contype="0" conaffinity="0" group="1" rgba="0 0.8 1 1" mesh="link4"/>
                            <body name="link5" pos="0 0 0.1135" quat="0.5 -0.5 0.5 -0.5">
                                <inertial pos="-3.0707e-05 0.015152 0.099848"
                                          quat="0.704002 -0.0654372 0.0666836 0.704026" mass="1.45"
                                          diaginertia="0.0057004 0.0057004 0.0057004"/>
                                <joint name="joint5" pos="0 0 0" axis="0 0 1" limited="true" range="-3.14 3.14"/>
                                <geom type="mesh" contype="0" conaffinity="0" group="1" rgba="1 1 1 1" mesh="link5"/>
                                <body name="link6" pos="0 0 0.1015" quat="0.7071067811865475 0.7071067811865475 0 0">
                                    <inertial pos="0 0.00058691 0.072051" quat="0.999992 -0.00407703 0 0" mass="0.21"
                                              diaginertia="0.00128044 0.00120857 0.000194485"/>
                                    <joint name="joint6" pos="0 0 0" axis="0 0 1" limited="true" range="-3.14 3.14"/>
                                    <geom type="mesh" contype="0" conaffinity="0" group="1"
                                          rgba="0.79216 0.81961 0.93333 1" mesh="link6"/>
                                    <!--stick与tip为末端执行器，长度为0.063,因此tip有一个0.063,stick有两个0.0315-->
                                    <body name="ee_link" pos="0 0 0.094">
                                        <inertial pos="0 0 0.015" mass="0.424"
                                                  diaginertia="0.00019875 0.00019875 0.00019080"/>
                                        <geom name="ft_sensor" type="cylinder" fromto="0 0 0  0 0 0.034" size="0.0375"/>
                                        <geom name="stick" type="cylinder" pos="0 0 0.0315" size="0.01 0.0315"/>
                                        <!--机器人末端-->
                                        <site name="ee" pos="0 0 0.063" rgba="1 0 0 0" size="0.01 0.01 0.01"
                                              type="sphere"/>
                                        <!--ee_link与link6，力传感器的力-->
                                        <site name="nft_sensor" pos="0 0 0" rgba="1 0 0 0" size="0.01 0.01 0.01"
                                              type="sphere"/>
                                        <!--tip与ee_link，接触点的力，专门定义dummy_body-->
                                        <body name="dummy_body" pos="0 0 0.063">
                                            <site name="contact_sensor" pos="0 0 0" rgba="1 0 0 0" size="0.01 0.01 0.01"
                                                  type="sphere"/>
                                            <inertial pos="0 0 0" mass="0.0" diaginertia="0 0 0"/>
                                            <geom type="sphere" pos="0 0 0" group="1" size="0.01 0.01 0.01"/>
                                        </body>
                                    </body>
                                </body>
                            </body>
                        </body>
                    </body>
                </body>
            </body>
        </body>
        <!-- -0.335时为原点 -->
        <body name="door" pos="-0.03 -0.735 0.3" quat="0 0 0 1">
            <body name="frame" pos="0 0.22 0" quat="0.7071067811865475 0 0 -0.7071067811865475">
                <inertial pos="0.3 0 0" quat="0.5 0.5 0.5 0.5" mass="7.85398" diaginertia="0.923301 0.764585 0.168533"/>
                <!-- 两根柱子 -->
                <geom size="0.03 0.3" pos="0.555 0 0" type="cylinder" rgba="1 1 1 1" group="1" name="r_frame"/>
                <!--              <geom size="0.03 0.3" pos="0.045 0 0" type="cylinder" rgba="1 1 1 1" group="1" name="l_frame"/>-->
                <body name="door_board" pos="0.3 0 0">
                    <inertial pos="0.0296816 -0.00152345 0" quat="0.701072 0 0 0.713091" mass="2.43455"
                              diaginertia="0.0913751 0.0521615 0.043714"/>
                    <joint name="hinge" pos="0.255 0 0" axis="0 0 1" range="0.0 1.5707" damping="1" frictionloss="1"
                           limited="true"/>
                    <geom size="0.22 0.02 .29" type="box" friction="1 1 1" group="1" name="panel" material="MatDarkWood"
                          condim="4"/>
                    <!--                  <body name="latch" pos="-0.175 0 -0.025">-->
                    <!--                      <inertial pos="-0.017762 0.0138544 0" quat="0.365653 0.605347 -0.36522 0.605365" mass="0.1" diaginertia="0.0483771 0.0410001 0.0111013" />-->
                    <!--                      <geom fromto="0 0 0 0 -0.125 0" size="0.025" type="cylinder" group="1" name="handle_base" material="MatMetal"/>-->
                    <!--&lt;!&ndash;                      <geom size="0.075 0.015 0.02" pos="0.075 -0.10 0" type="box" group="1" name="handle" material="MatMetal"/>&ndash;&gt;-->
                    <!--&lt;!&ndash;                      &lt;!&ndash; Don't render the door handle site by default &ndash;&gt;&ndash;&gt;-->
                    <!--&lt;!&ndash;                      <site name="handle" pos="0.125 -0.10 0" size="0.02" rgba="0 0 1 0" />&ndash;&gt;-->
                    <!--                      <site name="handle" pos="0 -0.125 0" size="0.025" rgba="0 0 1 1" />-->
                    <!--                  </body>-->
                </body>
            </body>
        </body>
        <!-- equality测试代码 -->
        <!--        <body name="anchor" pos="-0.1 -1.01164083 0.275 ">-->
        <!--            <geom type="box" size="0.01 0.01 0.01" />-->
        <!--            <joint type="free"/>-->
        <!--        </body>-->
        <site name="w_x" pos="0.1 0 0" rgba="1 0 0 1" size="0.01 0.1" type="cylinder" quat="1 0 1 0"/>
        <site name="w_y" pos="0 0.1 0" rgba="0 1 0 1" size="0.01 0.1" type="cylinder" quat="0 0 1 1"/>
        <site name="w_z" pos="0 0 0.1" rgba="0 0 1 1" size="0.01 0.1" type="cylinder" quat="0 0 1 0"/>
    </worldbody>
    <equality>
        <!--        <connect name="test" active="false" body1="dummy_body" body2="anchor" anchor="0 0 0" solref="2e-3 1"/>-->
        <connect name="robot2door" active="false" body1="dummy_body" body2="door_board" anchor="0.01 0 0"
                 solref="2e-3 1"/>
    </equality>
    <actuator>
        <motor name='motor1' ctrllimited="false" ctrlrange="-100 100" joint='joint1' gear="1"/>
        <motor name='motor2' ctrllimited="false" ctrlrange="-100 100" joint='joint2' gear="1"/>
        <motor name='motor3' ctrllimited="false" ctrlrange="-100 100" joint='joint3' gear="1"/>
        <motor name='motor4' ctrllimited="false" ctrlrange="-100 100" joint='joint4' gear="1"/>
        <motor name='motor5' ctrllimited="false" ctrlrange="-100 100" joint='joint5' gear="1"/>
        <motor name='motor6' ctrllimited="false" ctrlrange="-100 100" joint='joint6' gear="1"/>
    </actuator>
    <sensor>
        <!--检测接触点的力与力矩-->
        <force name="contact_force" site="contact_sensor"/>
        <torque name="contact_torque" site="contact_sensor"/>
        <touch name="contact_touch" site="contact_sensor"/>
        <!--检测nft传感器的力与力矩-->
        <force name="nft_force" site="nft_sensor"/>
        <torque name="nft_torque" site="nft_sensor"/>
    </sensor>
</mujoco>
